Workbook

Sheet Summary
A1: Cybersecurity test traceability: summary
A2: All counts are formulas over the other sheets. Update the "Test status" column there (drop-down) and the numbers here follow.
A4: Sheet | B4: Source | C4: Requirements | D4: Not started | E4: Designed | F4: Implemented | G4: Passed | H4: Failed | I4: Blocked
A5: SRS ch23 | B5: SRS rev. 731696, chapter 23 (Draft) | C5: =COUNTA('SRS ch23'!A2:A1000) -> 249 | D5: =COUNTIF('SRS ch23'!I2:I1000,"Not started") -> 249 | E5: =COUNTIF('SRS ch23'!I2:I1000,"Designed") -> 0 | F5: =COUNTIF('SRS ch23'!I2:I1000,"Implemented") -> 0 | G5: =COUNTIF('SRS ch23'!I2:I1000,"Passed") -> 0 | H5: =COUNTIF('SRS ch23'!I2:I1000,"Failed") -> 0 | I5: =COUNTIF('SRS ch23'!I2:I1000,"Blocked") -> 0
A6: Concept | B6: Cybersecurity Concept (Polarion, readyForReview) | C6: =COUNTA(Concept!A2:A1000) -> 41 | D6: =COUNTIF(Concept!L2:L1000,"Not started") -> 41 | E6: =COUNTIF(Concept!L2:L1000,"Designed") -> 0 | F6: =COUNTIF(Concept!L2:L1000,"Implemented") -> 0 | G6: =COUNTIF(Concept!L2:L1000,"Passed") -> 0 | H6: =COUNTIF(Concept!L2:L1000,"Failed") -> 0 | I6: =COUNTIF(Concept!L2:L1000,"Blocked") -> 0
A7: Technical | B7: Technical Cybersecurity Concept (Polarion, readyForReview) | C7: =COUNTA(Technical!A2:A1000) -> 30 | D7: =COUNTIF(Technical!L2:L1000,"Not started") -> 30 | E7: =COUNTIF(Technical!L2:L1000,"Designed") -> 0 | F7: =COUNTIF(Technical!L2:L1000,"Implemented") -> 0 | G7: =COUNTIF(Technical!L2:L1000,"Passed") -> 0 | H7: =COUNTIF(Technical!L2:L1000,"Failed") -> 0 | I7: =COUNTIF(Technical!L2:L1000,"Blocked") -> 0
A8: Total | C8: =SUM(C5:C7) -> 320 | D8: =SUM(D5:D7) -> 320 | E8: =SUM(E5:E7) -> 0 | F8: =SUM(F5:F7) -> 0 | G8: =SUM(G5:G7) -> 0 | H8: =SUM(H5:H7) -> 0 | I8: =SUM(I5:I7) -> 0
A10: SRS chapter 23 by security domain
A11: Security domain | B11: Requirements | C11: With open [X] choice | D11: Without verification criteria
A12: DTLS 1.3 link: SOW2-Vehicle ECU | B12: =COUNTIF('SRS ch23'!F2:F1000,A12) -> 90 | C12: =COUNTIFS('SRS ch23'!F2:F1000,A12,'SRS ch23'!C2:C1000,"*[X]*") -> 0 | D12: =COUNTIFS('SRS ch23'!F2:F1000,A12,'SRS ch23'!E2:E1000,"") -> 18
A13: SOW2-SOW1 (camera) auth & video | B13: =COUNTIF('SRS ch23'!F2:F1000,A13) -> 57 | C13: =COUNTIFS('SRS ch23'!F2:F1000,A13,'SRS ch23'!C2:C1000,"*[X]*") -> 0 | D13: =COUNTIFS('SRS ch23'!F2:F1000,A13,'SRS ch23'!E2:E1000,"") -> 8
A14: Secure debug | B14: =COUNTIF('SRS ch23'!F2:F1000,A14) -> 39 | C14: =COUNTIFS('SRS ch23'!F2:F1000,A14,'SRS ch23'!C2:C1000,"*[X]*") -> 15 | D14: =COUNTIFS('SRS ch23'!F2:F1000,A14,'SRS ch23'!E2:E1000,"") -> 0
A15: SPI flash secure interface | B15: =COUNTIF('SRS ch23'!F2:F1000,A15) -> 35 | C15: =COUNTIFS('SRS ch23'!F2:F1000,A15,'SRS ch23'!C2:C1000,"*[X]*") -> 24 | D15: =COUNTIFS('SRS ch23'!F2:F1000,A15,'SRS ch23'!E2:E1000,"") -> 1
A16: DRAM secure interface | B16: =COUNTIF('SRS ch23'!F2:F1000,A16) -> 28 | C16: =COUNTIFS('SRS ch23'!F2:F1000,A16,'SRS ch23'!C2:C1000,"*[X]*") -> 13 | D16: =COUNTIFS('SRS ch23'!F2:F1000,A16,'SRS ch23'!E2:E1000,"") -> 0
A17: Total | B17: =SUM(B12:B16) -> 249 | C17: =SUM(C12:C16) -> 52 | D17: =SUM(D12:D16) -> 27

Sheet SRS ch23
A1: Req ID | B1: Section | C1: Requirement (SOW2 SW, B-Sample SRS) | D1: Status | E1: Verification criteria (from SRS) | F1: Security domain | G1: CS test case ID(s) | H1: Test level | I1: Test status | J1: Notes
A2: MVC-107801 | B2: 23.1.1.1 PSK Loading | C2: The software shall retrieve the configured PSK from secure storage before initiating the DTLS 1.3 handshake. | D2: Draft | E2: Verify that the PSK is retrieved before transmission of the ClientHello message. Verify that handshake establishment is aborted if PSK retrieval fails. | F2: DTLS 1.3 link: SOW2-Vehicle ECU | I2: Not started
A3: MVC-107804 | B3: 23.1.1.1 PSK Loading | C3: The software shall retrieve the configured PSK identity associated with the communication interface before initiating the DTLS handshake. | D3: Draft | E3: Verify that the configured PSK identity is available before the ClientHello message is transmitted. Verify that handshake establishment is rejected when no valid PSK identity exists. | F3: DTLS 1.3 link: SOW2-Vehicle ECU | I3: Not started
A4: MVC-107803 | B4: 23.1.1.1 PSK Loading | C4: The software shall use the provisioned unique PSK associated with the configured SOW2–Vehicle ECU pairing during DTLS handshake key derivation. | D4: Draft | F4: DTLS 1.3 link: SOW2-Vehicle ECU | I4: Not started
A5: MVC-107805 | B5: 23.1.1.1 PSK Loading | C5: The software shall ensure that the retrieved PSK remains within the secure cryptographic boundary throughout the handshake process. | D5: Draft | E5: Verify that the PSK is never exposed outside the configured secure cryptographic boundary. | F5: DTLS 1.3 link: SOW2-Vehicle ECU | I5: Not started
A6: MVC-107796 | B6: 23.1.1.2 Random Generation | C6: The software shall obtain random values required for DTLS cryptographic operations from a Cryptographically Secure Pseudo-Random Number Generator (CSPRNG) seeded by the hardware TRNG. | D6: Draft | E6: Verify that random values are obtained from the approved random generation mechanism. | F6: DTLS 1.3 link: SOW2-Vehicle ECU | I6: Not started
A7: MVC-107795 | B7: 23.1.1.2 Random Generation | C7: The software shall generate a new DTLS Client Random value for every DTLS handshake before transmitting the ClientHello message. | D7: Draft | E7: Verify that a Client Random value is generated before the ClientHello message is transmitted. | F7: DTLS 1.3 link: SOW2-Vehicle ECU | I7: Not started
A8: MVC-107798 | B8: 23.1.1.2 Random Generation | C8: The software shall not reuse a previously generated Client Random value for any subsequent DTLS handshake. | D8: Draft | E8: Verify that a unique Client Random value is generated for every handshake. Verify that previously generated Client Random values are not reused. | F8: DTLS 1.3 link: SOW2-Vehicle ECU | I8: Not started
A9: MVC-107797 | B9: 23.1.1.2 Random Generation | C9: The software shall prevent reuse of random values across independent DTLS sessions. | D9: Draft | E9: Verify that random values are unique for independent DTLS sessions. Verify that DTLS processing is terminated when random number generation fails. | F9: DTLS 1.3 link: SOW2-Vehicle ECU | I9: Not started
A10: MVC-107807 | B10: 23.1.1.3 Ephemeral ECDHE Generation | C10: The software shall generate a new ephemeral ECDHE key pair before constructing the ClientHello message. | D10: Draft | E10: Verify that a new ECDHE key pair is generated for every handshake. | F10: DTLS 1.3 link: SOW2-Vehicle ECU | I10: Not started
A11: MVC-107811 | B11: 23.1.1.3 Ephemeral ECDHE Generation | C11: The software shall generate the ephemeral ECDHE key pair using the configured secp256r1 (P-256) named group. | D11: Draft | F11: DTLS 1.3 link: SOW2-Vehicle ECU | I11: Not started
A12: MVC-107809 | B12: 23.1.1.3 Ephemeral ECDHE Generation | C12: The software shall ensure that the generated ephemeral ECDHE key pair is associated only with the current DTLS handshake and not reuse an ephemeral ECDHE private key or its corresponding public key for any subsequent DTLS handshake. | D12: Draft | E12: Verify that the corresponding public key is included in the DTLS key_share extension. Verify that each DTLS handshake uses a unique ephemeral ECDHE key pair. Verify that previously generated ephemeral ECDHE key pairs are never reused. | F12: DTLS 1.3 link: SOW2-Vehicle ECU | I12: Not started
A13: MVC-107812 | B13: 23.1.1.3 Ephemeral ECDHE Generation | C13: The software shall ensure that the ephemeral ECDHE private key remains within the configured secure cryptographic boundary throughout the DTLS handshake. | D13: Draft | E13: Verify that the ephemeral private key remains protected within the secure cryptographic boundary. | F13: DTLS 1.3 link: SOW2-Vehicle ECU | I13: Not started
A14: MVC-107813 | B14: 23.1.2 ClientHello Construction | C14: The software shall operate as the DTLS 1.3 Client for the SOW2–Vehicle ECU secure communication interface. | D14: Draft | E14: Verify that SOW2 initiates the DTLS handshake as the DTLS Client. | F14: DTLS 1.3 link: SOW2-Vehicle ECU | I14: Not started
A15: MVC-107806 | B15: 23.1.2 ClientHello Construction | C15: The software shall include DTLS 1.3 as the supported protocol version in the supported_versions extension in the ClientHello message. | D15: Draft | E15: Verify that the ClientHello advertises DTLS 1.3. Verify that the handshake is terminated if DTLS 1.3 is not negotiated. | F15: DTLS 1.3 link: SOW2-Vehicle ECU | I15: Not started
A16: MVC-107821 | B16: 23.1.2 ClientHello Construction | C16: The software shall include only supported DTLS 1.3 AEAD cipher suites in the ClientHello message. | D16: Draft | E16: Verify that only configured cipher suites are advertised. | F16: DTLS 1.3 link: SOW2-Vehicle ECU | I16: Not started
A17: MVC-107819 | B17: 23.1.2 ClientHello Construction | C17: The software shall include TLS_AES_128_GCM_SHA256 in the ClientHello message as a supported cipher suite for DTLS session establishment with the Vehicle ECU. | D17: Draft | E17: Verify that TLS_AES_128_GCM_SHA256 is advertised | F17: DTLS 1.3 link: SOW2-Vehicle ECU | I17: Not started
A18: MVC-107825 | B18: 23.1.2 ClientHello Construction | C18: The software shall advertise the configured PSK-DHE key exchange mode with psk_dhe_ke in the ClientHello message. | D18: Draft | E18: Verify that the ClientHello advertises the configured PSK-DHE key exchange mode. Verify that unauthorized key exchange modes are not advertised. Verify that handshake establishment fails when the negotiated key exchange mode differs from the configured mode. | F18: DTLS 1.3 link: SOW2-Vehicle ECU | I18: Not started
A19: MVC-107823 | B19: 23.1.2 ClientHello Construction | C19: The software shall encode the configured PSK identity using the configured identity format, encoding, and length before including it in the pre_shared_key extension of the ClientHello message. | D19: Draft | F19: DTLS 1.3 link: SOW2-Vehicle ECU | I19: Not started
A20: MVC-107816 | B20: 23.1.2 ClientHello Construction | C20: The software shall include the generated ephemeral ECDHE public key in the DTLS key_share extension of the ClientHello message. | D20: Draft | E20: Verify that the generated ECDHE public key is included in the key_share extension. Verify that the transmitted public key corresponds to the generated key pair. Verify that only the public key is transmitted. | F20: DTLS 1.3 link: SOW2-Vehicle ECU | I20: Not started
A21: MVC-107815 | B21: 23.1.2 ClientHello Construction | C21: The software shall terminate the DTLS handshake if the generated ECDHE public key cannot be included in the key_share extension. | D21: Draft | E21: Verify that the handshake is terminated if the key_share extension cannot be generated. | F21: DTLS 1.3 link: SOW2-Vehicle ECU | I21: Not started
A22: MVC-107818 | B22: 23.1.2 ClientHello Construction | C22: The software shall include the generated ClientRandom value in the ClientHello message | D22: Draft | F22: DTLS 1.3 link: SOW2-Vehicle ECU | I22: Not started
A23: MVC-107817 | B23: 23.1.2 ClientHello Construction | C23: The software shall maintain the DTLS handshake transcript from the ClientHello until handshake completion by appending handshake messages in the order transmitted or successfully received. | D23: Draft | F23: DTLS 1.3 link: SOW2-Vehicle ECU | I23: Not started
A24: MVC-107810 | B24: 23.1.3 HelloRetryRequest | C24: The software shall maintain a retransmission buffer for transmitted DTLS handshake records until acknowledgement is received or retransmission is no longer required. | D24: Draft | E24: Verify that transmitted handshake records are retained in the retransmission buffer until acknowledged or no longer required. | F24: DTLS 1.3 link: SOW2-Vehicle ECU | I24: Not started
A25: MVC-107822 | B25: 23.1.3 HelloRetryRequest | C25: The software shall start a retransmission timer after transmitting each DTLS handshake flight requiring acknowledgement. | D25: Draft | E25: Verify that the retransmission timer starts after transmission of a handshake flight requiring acknowledgement. | F25: DTLS 1.3 link: SOW2-Vehicle ECU | I25: Not started
A26: MVC-107820 | B26: 23.1.3 HelloRetryRequest | C26: The software shall retransmit unacknowledged DTLS handshake records when the retransmission timer expires. | D26: Draft | E26: Verify that unacknowledged handshake records are retransmitted after retransmission timeout expiration. | F26: DTLS 1.3 link: SOW2-Vehicle ECU | I26: Not started
A27: MVC-107826 | B27: 23.1.3 HelloRetryRequest | C27: The software shall apply the configured retransmission timeout, timeout backoff policy, maximum retransmission attempts, and handshake timeout during retransmission processing. | D27: Draft | E27: Verify that the configured timeout, timeout backoff policy, retry limit, and handshake timeout are applied during retransmission processing. | F27: DTLS 1.3 link: SOW2-Vehicle ECU | I27: Not started
A28: MVC-107824 | B28: 23.1.3 HelloRetryRequest | C28: The software shall terminate the DTLS handshake if the configured handshake timeout expires or the maximum retransmission attempts are exceeded. | D28: Draft | E28: Verify that the DTLS handshake is terminated when the configured retry limit or handshake timeout is exceeded. | F28: DTLS 1.3 link: SOW2-Vehicle ECU | I28: Not started
A29: MVC-107964 | B29: 23.1.4 ServerHello Validation | C29: The software shall validate in ServerHello: the selected PSK identity received from the Vehicle ECU against the configured PSK identity. the selected cipher suite matches one of the configured supported cipher suites. the selected key exchange mode matches the configured PSK-DHE mode. the Vehicle ECU ECDHE public key before computing the shared secret. | D29: Draft | F29: DTLS 1.3 link: SOW2-Vehicle ECU | I29: Not started
A30: MVC-107969 | B30: 23.1.4 ServerHello Validation | C30: The software shall verify that the cipher suite selected by the Vehicle ECU is one of the advertised and configured cipher suites. | D30: Draft | E30: Verify that deprecated or unauthorized cipher suites are not advertised. Verify that the handshake is terminated when an unauthorized cipher suite is negotiated. | F30: DTLS 1.3 link: SOW2-Vehicle ECU | I30: Not started
A31: MVC-107968 | B31: 23.1.4 ServerHello Validation | C31: The software shall terminate the DTLS handshake if the Vehicle ECU selects a cipher suite that was not advertised or is not supported. | D31: Draft | F31: DTLS 1.3 link: SOW2-Vehicle ECU | I31: Not started
A32: MVC-107971 | B32: 23.1.4 ServerHello Validation | C32: The software shall terminate the DTLS handshake if any mandatory ServerHello validation fails. | D32: Draft | F32: DTLS 1.3 link: SOW2-Vehicle ECU | I32: Not started
A33: MVC-107970 | B33: 23.1.4 ServerHello Validation | C33: The software shall record a DTLS handshake failure in the security log when protocol version negotiation fails due to an unsupported or unauthorized protocol version. | D33: Draft | E33: Verify generation of a security event for protocol version negotiation failure like recording. | F33: DTLS 1.3 link: SOW2-Vehicle ECU | I33: Not started
A34: MVC-107993 | B34: 23.1.5 Secret Derivation | C34: The software shall compute the ECDHE shared secret using the locally generated ECDHE private key and the validated Vehicle ECU public key. | D34: Draft | E34: Verify successful shared secret generation. Verify that shared secret generation fails when public key validation fails. | F34: DTLS 1.3 link: SOW2-Vehicle ECU | I34: Not started
A35: MVC-107991 | B35: 23.1.5 Secret Derivation | C35: The software shall derive the DTLS handshake secrets using the configured PSK, the ECDHE shared secret, and the DTLS handshake transcript before processing encrypted handshake messages. | D35: Draft | E35: Verify successful handshake secret derivation. Verify that derivation fails when any required input is invalid. Verify that encrypted handshake messages are processed only after handshake traffic secrets are derived. | F35: DTLS 1.3 link: SOW2-Vehicle ECU | I35: Not started
A36: MVC-107982 | B36: 23.1.5 Secret Derivation | C36: The software shall derive the DTLS handshake write keys, write IVs, and sequence number encryption keys from the handshake traffic secrets. | D36: Draft | F36: DTLS 1.3 link: SOW2-Vehicle ECU | I36: Not started
A37: MVC-107995 | B37: 23.1.6 EncryptedExtensions | C37: The software shall receive the DTLS EncryptedExtensions message after successful derivation of the server handshake traffic keys. | D37: Draft | E37: Verify that the software processes the EncryptedExtensions message only after the server handshake traffic keys have been derived. | F37: DTLS 1.3 link: SOW2-Vehicle ECU | I37: Not started
A38: MVC-107994 | B38: 23.1.6 EncryptedExtensions | C38: The software shall decrypt the received EncryptedExtensions message using the server handshake traffic keys before processing its contents. | D38: Draft | E38: Verify that the software decrypts the EncryptedExtensions message using the server handshake traffic keys. Verify that the software validates the decrypted EncryptedExtensions message before continuing the DTLS handshake. | F38: DTLS 1.3 link: SOW2-Vehicle ECU | I38: Not started
A39: MVC-107980 | B39: 23.1.6 EncryptedExtensions | C39: The software shall terminate the DTLS handshake if the EncryptedExtensions message cannot be successfully decrypted or validated. | D39: Draft | E39: Verify that the DTLS handshake is terminated if EncryptedExtensions decryption or validation fails. | F39: DTLS 1.3 link: SOW2-Vehicle ECU | I39: Not started
A40: MVC-107977 | B40: 23.1.7 Server Finished Verification | C40: The software shall receive and process the encrypted Finished message transmitted by the Vehicle ECU after successful completion of the preceding DTLS handshake messages. | D40: Draft | E40: Verify that the encrypted Finished message is processed only after the required handshake secrets have been successfully derived. Verify successful decryption of a valid Finished message. Verify rejection when decryption fails. | F40: DTLS 1.3 link: SOW2-Vehicle ECU | I40: Not started
...

Sheet Concept
A1: Req ID | B1: Outline | C1: Section | D1: Requirement | E1: CAL | F1: Verification method | G1: Verification criteria (from concept) | H1: Satisfied by (technical reqs) | I1: Satisfies (concept reqs) | J1: Proposed test ID | K1: Test level | L1: Test status | M1: Notes
A2: MVC-103063 | B2: 2.2.1.1.1-1 | C2: SOW1 - SOW2 interface > ROT key storage | D2: The system shall store the trusted 2048bit Samsung Root Public Key in OTP memory. | E2: CAL 2 | F2: Test | G2: Verify that the trusted 2048-bit Samsung Root Public Key is provisioned in OTP memory. Verify that the key remains unchanged after a system reset or restart and cannot be overwritten through normal system interfaces. | H2: MVC-106562 | J2: (covered by CS-SOW1-001) | K2: System | L2: Not started
A3: MVC-107642 | B3: 2.2.1.1.2-1 | C3: SOW1 - SOW2 interface > SOW1 device authentication | D3: The system shall authenticate the Imager by verifying the digital signature received from the Imager over the I2C interface using the provisioned Samsung Root Public Key. | E3: CAL 2 | F3: Test | G3: Verify that the system authenticates the Imager by verifying the digital signature received over I2C using the provisioned Samsung Root Public Key. Authentication shall succeed for a valid signature and fail for an invalid signature, modified authentication data, or a signature generated using a non-trusted key. | H3: MVC-106561, MVC-106565, MVC-106563 | J3: (covered by CS-SOW1-002, CS-SOW1-003, CS-SOW1-004) | K3: System | L3: Not started
A4: MVC-107641 | B4: 2.2.1.1.2-2 | C4: SOW1 - SOW2 interface > SOW1 device authentication | D4: The system shall use RSASSA-PSS with SHA-256 to verify the Imager's digital signature. | E4: CAL 2 | F4: Test | G4: Verify that the Imager signature verification operation uses RSASSA-PSS with SHA-256. Confirm successful verification using a valid test signature generated with the corresponding private key and failure when the signature, signed data, or public key is modified. | K4: System | L4: Not started | M4: No technical requirement is linked to this one in the TECH workbook. MVC-106563 (CS-SOW1-004) verifies RSASSA-PSS with SHA-256, so the link is probably missing in Polarion: confirm
A5: MVC-103053 | B5: 2.2.1.1.2-3 | C5: SOW1 - SOW2 interface > SOW1 device authentication | D5: The system shall retry the Imager authentication process up to three times if the expected authentication data is failed to be received. | E5: CAL 2 | F5: Test | G5: Verify that when the expected authentication data is not received, the system retries the Imager authentication process according to the configured retry policy, up to the specified maximum of three retries. Verify that authentication proceeds successfully if the expected data is received within the allowed attempts. | H5: MVC-106566 | J5: (covered by CS-SOW1-005) | K5: System | L5: Not started
A6: MVC-103051 | B6: 2.2.1.1.2-4 | C6: SOW1 - SOW2 interface > SOW1 device authentication | D6: The system shall terminate the Imager authentication process if authentication is not successfully completed within the configured maximum number of retry attempts | E6: CAL 2 | F6: Test | G6: Verify that the Imager authentication process terminates when authentication cannot be completed within the configured maximum retry attempts. Confirm that the system does not continue retrying indefinitely and does not treat the Imager as authenticated after termination. | H6: MVC-106569 | J6: (covered by CS-SOW1-006) | K6: System | L6: Not started
A7: MVC-103040 | B7: 2.2.1.1.3-1 | C7: SOW1 - SOW2 interface > Session Key sharing | D7: Following successful authentication, The system shall extract 2048-bit device public key from the Imager's authentication data. | E7: CAL 2 | F7: Test | G7: Verify that, following successful Imager authentication, the system correctly extracts the 2048-bit device public key from the Imager's authentication data. Confirm that the extracted key matches the reference key and that missing, malformed, or incorrectly sized public-key data is not accepted as a valid key. | H7: MVC-106577 | J7: (covered by CS-SOW1-012) | K7: System | L7: Not started
A8: MVC-103057 | B8: 2.2.1.1.3-2 | C8: SOW1 - SOW2 interface > Session Key sharing | D8: The system shall generate a 256-bit cryptographically random session key (SSK) following successful Imager authentication. | E8: CAL 2 | F8: Test | G8: Verify that the system generates a 256-bit session key (SSK) following successful Imager authentication. Confirm that the generated key has the required 256-bit length and that a new session key is generated for each new secure session. | H8: MVC-106568 | J8: (covered by CS-SOW1-010) | K8: System | L8: Not started
A9: MVC-103042 | B9: 2.2.1.1.3-3 | C9: SOW1 - SOW2 interface > Session Key sharing | D9: The system shall use a CSPRNG compliant with NIST SP 800-90A and seeded by a hardware TRNG to generate the 256-bit session key. | E9: CAL 2 | F9: Test | G9: Verify that session-key generation uses a CSPRNG compliant with NIST SP 800-90A and seeded by a hardware TRNG. Verify that session-key generation fails securely if the required random-number generation mechanism is unavailable or reports an error. | H9: MVC-106560 | J9: (covered by CS-SOW1-011) | K9: System | L9: Not started
A10: MVC-103055 | B10: 2.2.1.1.3-4 | C10: SOW1 - SOW2 interface > Session Key sharing | D10: The system shall encrypt the session key and selected row information using the 2048-bit device public key with RSAES-OAEP and SHA-256. Note: Row information format is defined by Samsung, which is described in ‘5 Key sharing’ chapter in S5K3B6SA - Cybersecurity Application note documnet. | E10: CAL 2 | F10: Test | G10: Verify that the system encrypts the 256-bit SSK and selected row information using the extracted 2048-bit device public key with RSAES-OAEP and SHA-256. Confirm that the intended recipient can decrypt the output using the corresponding private key and recover the expected session key and row information. Verify that decryption using a different private key fails. | H10: MVC-106576, MVC-108741, MVC-106574, MVC-106580 | J10: (covered by CS-SOW1-007, CS-SOW1-008, CS-SOW1-009, CS-SOW1-013) | K10: System | L10: Not started
A11: MVC-103034 | B11: 2.2.1.1.3-5 | C11: SOW1 - SOW2 interface > Session Key sharing | D11: The system shall transmit the 2048bit Encrypted Session Key and row information to the Imager for secure session establishment. | E11: CAL 2 | F11: Test | G11: Verify that, after successful session-key encryption, the system transmits the encrypted session key and selected row information to the Imager. Confirm that the transmitted message contains the required data in the agreed format and that the encrypted session key corresponds to the generated SSK. | H11: MVC-106578 | J11: (covered by CS-SOW1-014) | K11: System | L11: Not started
A12: MVC-113706 | B12: 2.2.1.1.3-6 | C12: SOW1 - SOW2 interface > Session Key sharing | D12: The system shall not expose the active session key through any accessible interface during the active secure session. | E12: CAL 2 | F12: Test | G12: Verify that the active SSK is not exposed through accessible interfaces during an active secure session. Inspect relevant diagnostic, debug, communication, and externally accessible interfaces to confirm that the key is not returned or transmitted in plaintext. | H12: MVC-106571 | J12: (covered by CS-SOW1-015) | K12: System | L12: Not started
A13: MVC-103046 | B13: 2.2.1.1.3-7 | C13: SOW1 - SOW2 interface > Session Key sharing | D13: The system shall retry secure session establishment up to three times if the expected response is failed to be received. | E13: CAL 2 | F13: Test | G13: Verify that the system retries secure session establishment when the expected response is not received. Confirm that the retry behavior follows the specified maximum of three retries and that the system can establish the session if a valid response is received within the allowed attempts. | H13: MVC-106567 | J13: (covered by CS-SOW1-016) | K13: System | L13: Not started
A14: MVC-103044 | B14: 2.2.1.1.3-8 | C14: SOW1 - SOW2 interface > Session Key sharing | D14: The system shall terminate secure session establishment if a secure session is not successfully established after three retry attempts. | E14: CAL 2 | F14: Test | G14: Verify that secure session establishment terminates when the session cannot be established after the permitted three retry attempts. Confirm that the system does not report a successful session, activate the SSK for secured communication, or continue retrying indefinitely. | H14: MVC-106581 | J14: (covered by CS-SOW1-017) | K14: System | L14: Not started
A15: MVC-103036 | B15: 2.2.1.1.3-9 | C15: SOW1 - SOW2 interface > Session Key sharing | D15: The system shall require establishment of a new secure session, including full SOW1 authentication and generation of a new session key (SSK), after session expiry, system reset, system restart, session termination, or detection of a security failure. | E15: CAL 2 | F15: Test | G15: Verify that a new secure session, including full SOW1 authentication and generation of a new SSK, is required after each specified trigger: session expiry, system reset, system restart, session termination, and detection of a security failure. Confirm that the previous session is no longer accepted and that secured communication resumes only after successful reauthentication and session establishment. | H15: MVC-106573 | J15: (covered by CS-SOW1-018) | K15: System | L15: Not started
A16: MVC-119708 | B16: 2.2.1.1.4-1 | C16: SOW1 - SOW2 interface > Streaming video Requirements (SOW1 -> SOW2) | D16: The system shall not accept SOW1 secured video stream data as trusted before successful SOW1 device authentication and secure session establishment. | E16: CAL 2 | F16: Test | G16: Verify that SOW1 secured video stream data is not accepted or processed as trusted before successful SOW1 device authentication and secure session establishment. Confirm that frames received before authentication, during failed session establishment, and after session termination are not treated as trusted data. | H16: MVC-109120 | J16: (covered by CS-SOW1-024) | K16: System | L16: Not started
... A26: MVC-113702 | B26: 2.2.1.1.5-4 | C26: SOW1 - SOW2 interface > SOW1 Commands Requirements (SOW2 -> SOW1) | D26: The system shall include a monotonically increasing Counter in each SOW1 control command transmitted. | E26: CAL 2 | F26: Test | G26: Verify that each transmitted SOW1 control command contains a monotonically increasing counter. Confirm that the counter increases for successive commands and does not repeat or decrease during normal operation within a session. | H26: MVC-109121 | J26: (covered by CS-SOW1-030) | K26: System | L26: Not started
A27: MVC-103061 | B27: 2.2.3-1 | C27: System Cybersecurity Requirements > Secure Debug | D27: The system shall keep the hardware debug interfaces, including JTAG, locked by default when the ECU operates in locked mode and shall permit debug unlocking through an authorized challenge-response authentication mechanism. | E27: CAL 1 | F27: Test | G27: Set the ECU to locked mode and attempt to access the hardware debug interfaces, including JTAG, without completing an authorized challenge-response transaction. The verification passes if the interfaces remain locked by default, failed or unauthorized transactions do not unlock them, and access is enabled only after successful completion of an authorized challenge-response transaction. | J27: CS-DBG-001 | K27: System | L27: Not started
A28: MVC-103060 | B28: 2.2.3-2 | C28: System Cybersecurity Requirements > Secure Debug | D28: The system shall receive debug-unlock requests through the designated debug service communication interface during runtime and shall keep hardware debug access locked until successful authentication. | E28: CAL 1 | F28: Test | G28: Send a valid debug-unlock request through the designated debug service communication interface while the ECU is operating at runtime. The verification passes if the request is received and processed through the designated interface and the hardware debug access remains locked until the authentication process completes successfully. | J28: CS-DBG-002 | K28: System | L28: Not started
A29: MVC-103050 | B29: 2.2.3-3 | C29: System Cybersecurity Requirements > Secure Debug | D29: The system shall generate a fresh random debug authentication challenge using the platform True Random Number Generator (TRNG) after receiving a valid debug unlock request. | E29: CAL 1 | F29: Review | G29: Review the software design, implementation, and call flow. The verification passes if the platform TRNG is used as the source for generating a fresh random debug authentication challenge and challenge generation is triggered only after receipt of a valid debug-unlock request. | J29: CS-DBG-003 | K29: System | L29: Not started
A30: MVC-103043 | B30: 2.2.3-4 | C30: System Cybersecurity Requirements > Secure Debug | D30: The system shall generate a unique debug authentication challenge for each debug unlock request and shall enforce a limited challenge validity period defined by the OEM. | E30: CAL 1 | F30: Test | G30: Initiate multiple debug-unlock transactions and record the generated challenges. The verification passes if each transaction receives a unique challenge, an otherwise valid response is accepted only within the OEM-defined challenge validity period, and a response received after expiry is rejected. | J30: CS-DBG-004 | K30: System | L30: Not started
A31: MVC-103047 | B31: 2.2.3-6 | C31: System Cybersecurity Requirements > Secure Debug | D31: The system shall independently compute the expected AES-CMAC value using the derived DebugUnlockSessionKey and the active debug-unlock transaction context within the secure execution environment upon receiving a debug-unlock response. | E31: CAL 1 | F31: Review | G31: Review the software architecture, implementation, and debug-unlock processing flow. The verification passes if, upon receiving a debug-unlock response, the system independently computes the expected AES-CMAC value inside the secure execution environment using the derived DebugUnlockSessionKey and the active debug-unlock transaction context. | J31: CS-DBG-005 | K31: System | L31: Not started
A32: MVC-103037 | B32: 2.2.3-8 | C32: System Cybersecurity Requirements > Secure Debug | D32: The system shall reject any expired, reused, malformed, invalid, unauthorized, or cryptographically incorrect debug unlock response. | E32: CAL 1 | F32: Test | G32: Submit separate debug-unlock responses representing expired, reused, malformed, invalid, unauthorized, and cryptographically incorrect cases. The verification passes if every tested response is rejected and the hardware debug interface remains locked. | J32: CS-DBG-006 | K32: System | L32: Not started
A33: MVC-103039 | B33: 2.2.3-10 | C33: System Cybersecurity Requirements > Secure Debug | D33: The system shall unlock the hardware debug interface only after successful verification of the debug unlock response. | E33: CAL 1 | F33: Test | G33: Execute debug-unlock transactions using a successfully verified response and using failed, incomplete, or incorrect responses. The verification passes if the hardware debug interface is unlocked only after successful verification of the debug-unlock response and remains locked in all other cases. | J33: CS-DBG-007 | K33: System | L33: Not started
A34: MVC-105883 | B34: 2.2.3-11 | C34: System Cybersecurity Requirements > Secure Debug | D34: The system shall derive a debug unlock session key using a CMAC Key Derivation Function (KDF) | E34: CAL 1 | F34: Test | G34: Derive a DebugUnlockSessionKey using defined test inputs and compare the generated key against the output of an approved reference CMAC Key Derivation Function. The verification passes if the derived key matches the expected CMAC-KDF output for all tested input sets. | J34: CS-DBG-008 | K34: System | L34: Not started
A35: MVC-105881 | B35: 2.2.3-12 | C35: System Cybersecurity Requirements > Secure Debug | D35: The system shall store the derived debug unlock session key only in the DRAM. | E35: CAL 1 | F35: Review | G35: Review the memory architecture, memory map, linker configuration, and key-handling implementation. The verification passes if the derived DebugUnlockSessionKey is stored only in its designated DRAM location and no copy of the key is stored in non-DRAM or persistent memory. | J35: CS-DBG-009 | K35: System | L35: Not started
A36: MVC-105887 | B36: 2.2.3-13 | C36: System Cybersecurity Requirements > Secure Debug | D36: The system shall securely erase the derived debug unlock session key, and intermediate cryptographic material from the DRAM after completion of the debug session, upon session termination, or upon authentication failure. | E36: CAL 1 | F36: Test | G36: Generate a DebugUnlockSessionKey and intermediate cryptographic material, then separately trigger debug-session completion, session termination, and authentication failure. The verification passes if inspection of the allocated DRAM locations after each trigger confirms that the derived key and intermediate cryptographic material are no longer recoverable. | J36: CS-DBG-010 | K36: System | L36: Not started
A37: MVC-103038 | B37: 2.2.3-14 | C37: System Cybersecurity Requirements > Secure Debug | D37: The system shall permit debug access only for an authorized and time-limited debug session and shall automatically relock the debug interface after session timeout, Power-On Reset (POR), completion of debug activities, lifecycle transition, or detection of security violations. | E37: CAL 1 | F37: Test | G37: Complete an authorized debug-unlock transaction and verify that debug access is available only during the authorized, time-limited session. Separately trigger session timeout, Power-On Reset, completion of debug activities, lifecycle transition, and detection of a security violation. The verification passes if the hardware debug interface automatically relocks after every specified trigger and unauthorized access is not permitted. | J37: CS-DBG-011 | K37: System | L37: Not started
A38: MVC-103049 | B38: 2.2.3-15 | C38: System Cybersecurity Requirements > Secure Debug | D38: The system shall limit repeated failed debug authentication attempts and temporarily block further attempts after a configurable threshold is reached. | E38: CAL 1 | F38: Test | G38: Perform consecutive failed debug-authentication attempts using the configured failure threshold. The verification passes if further authentication attempts are temporarily blocked when the threshold is reached, attempts during the blocking period are rejected, and new attempts are permitted only after the configured temporary blocking period expires. | J38: CS-DBG-012 | K38: System | L38: Not started
... A42: MVC-116572 | B42: 2.2.4-1 | C42: System Cybersecurity Requirements > Hardware Security Protection | D42: The ECU shall protect hardware interfaces, control functions and firmware against unauthorized external access and manipulation. | E42: CAL 2 | F42: Test | G42: Verify that unauthorized external access attempts to hardware interfaces are prevented or rejected. Verify that unauthorized external attempts to disrupt hardware functions, including reset or power control functions, do not cause unintended disruption of ECU operation. Verify that unauthorized external attempts to access, modify, or replace ECU firmware are prevented and do not result in execution of unauthorized firmware. | J42: CS-HWP-001 | K42: System | L42: Not started

Sheet Technical
A1: Req ID | B1: Outline | C1: Section | D1: Requirement | E1: CAL | F1: Verification method | G1: Verification criteria (from concept) | H1: Satisfied by (technical reqs) | I1: Satisfies (concept reqs) | J1: Proposed test ID | K1: Test level | L1: Test status | M1: Notes
A2: MVC-106562 | B2: 2.2.3.1-1 | C2: Secure Communication (SOW2 - SOW1) > ROT key storage | D2: The system shall store the trusted 2048bit Samsung Root Public Key in OTP memory. | E2: CAL 2 | F2: Test | G2: Verify that the Samsung Root RSA public key is stored in the defined OTP/eFuse location. Verify that the configured RSA key size is 2048 bits. Verify that the OTP storage area is configured as immutable after provisioning. Verify that the Secure Boot authentication function retrieves the Root RSA public key from the defined immutable storage location. | I2: MVC-103063 | J2: CS-SOW1-001 | K2: System | L2: Not started
A3: MVC-106561 | B3: 2.2.3.2-1 | C3: Secure Communication (SOW2 - SOW1) > Device Authentication Requirements | D3: The system shall request the SOW1 device authentication data, including Device_n, KID, and Sig_device, from SOW1 over the I2C interface after reset or before starting the secure session. | E3: CAL 2 | F3: Test | G3: 1. Reset the system and monitor I2C traffic to verify that the system requests SOW1 authentication data. 2. Repeat the test when a secure session must be established before secure communication starts. 3. Verify that the request is sent to the configured SOW1 device over I2C. 4. Verify that the request-response handling supports the required fields Device_n, KID, and Sig_device. 5. Verify that the system handles a missing or incomplete response according to the defined authentication error and retry behavior. | I3: MVC-107642 | J3: CS-SOW1-002 | K3: System | L3: Not started
A4: MVC-106565 | B4: 2.2.3.2-2 | C4: Secure Communication (SOW2 - SOW1) > Device Authentication Requirements | D4: The system shall authenticate SOW1 by verifying Sig_device over Device_n and KID using the trusted RSA-2048 Samsung Root Public Key. | E4: CAL 2 | F4: Test | G4: 1. Provide authentication data containing a valid Device_n, KID, and Sig_device, with a signature generated using the private key corresponding to the trusted Samsung Root Public Key. 2. Verify that authentication succeeds when the signature covers the specified Device_n and KID values. 3. Modify Device_n without updating the signature and verify that authentication fails. 4. Modify KID without updating the signature and verify that authentication fails. 5. Provide an invalid signature or one generated using an untrusted private key and verify that authentication fails. 6. Verify that failed authentication does not result in the SOW1 device being marked as authenticated. | I4: MVC-107642 | J4: CS-SOW1-003 | K4: System | L4: Not started
A5: MVC-106563 | B5: 2.2.3.2-3 | C5: Secure Communication (SOW2 - SOW1) > Device Authentication Requirements | D5: The system shall use RSASSA-PSS whith SHA-256 to verify the Imager's digital signature (Sig_device). | E5: CAL 2 | F5: Test | G5: 1. Verify through cryptographic configuration or implementation inspection that Sig_device verification uses RSASSA-PSS with SHA-256. 2. Verify the configured RSA public-key size is 2048 bits. 4. Verify failure when the signature or signed data is modified. 5. Verify that signatures generated using a different verification scheme or incompatible parameters are not accepted as valid RSASSA-PSS/SHA-256 signatures | I5: MVC-107642 | J5: CS-SOW1-004 | K5: System | L5: Not started
A6: MVC-106566 | B6: 2.2.3.2-4 | C6: Secure Communication (SOW2 - SOW1) > Device Authentication Requirements | D6: The system shall retransmit the SOW1 authentication request up to three times if the expected authentication data is failed to be received. | E6: CAL 2 | F6: Test | G6: 1. Make the SOW1 authentication response unavailable and initiate authentication. 2. Monitor I2C traffic and count the authentication requests transmitted. 3. Verify that the system retransmits the request when expected authentication data is not received. 4. Verify that retransmission stops when valid authentication data is received or the retry limit is reached. 5. Repeat with a response arriving on the last permitted attempt. | I6: MVC-103053 | J6: CS-SOW1-005 | K6: System | L6: Not started
A7: MVC-106569 | B7: 2.2.3.2-5 | C7: Secure Communication (SOW2 - SOW1) > Device Authentication Requirements | D7: The system shall terminate the SOW1 authentication process if authentication is not successfully completed after three authentication attempts. | E7: CAL 2 | F7: Test | G7: 1. Prevent valid authentication data from being received for the entire permitted authentication-attempt sequence. 2. Verify that the authentication procedure terminates after the defined attempt limit. 3. Verify that the device remains unauthenticated. 4. Verify that session establishment and protected SOW1 operations do not proceed based on the failed authentication. 5. Verify that the system does not continue retransmitting authentication requests indefinitely. | I7: MVC-103051 | J7: CS-SOW1-006 | K7: System | L7: Not started
A8: MVC-106576 | B8: 2.2.3.3-1 | C8: Secure Communication (SOW2 - SOW1) > Row information requirements | D8: The system shall configure the row start value of Row_info_00 or Row_info_01 to either 0 or 1 to include the embedded header containing the video frame counter in the AES-CMAC input. Note: If Row start value set as 0, first line will be included as a AES-CMAC input. - If Row start value set as 1, second line will be included as a AES-CMAC input. | E8: CAL 2 | F8: Test | G8: 1. Configure the row-start value of Row_info_00 or Row_info_01 to 0 and verify that the first line, containing the embedded header and frame counter, is included in the AES-CMAC input. 2. Configure the row-start value to 1 and verify that the second line is used as the starting line. 3. Verify that the row-start value is correctly encoded in the transmitted row information. 4. Verify that the AES-CMAC input rows correspond to the configured starting value. 5. Verify that values other than 0 and 1 are rejected or handled according to the defined configuration-validation policy. | I8: MVC-103055 | J8: CS-SOW1-007 | K8: System | L8: Not started
A9: MVC-108741 | B9: 2.2.3.3-2 | C9: Secure Communication (SOW2 - SOW1) > Row information requirements | D9: The system shall configure the row interval to be at least 10 for Merge Compressed or Merged output mode (RAW12, RAW14, RAW16, RAW20, and RAW24), and at least 30 for Line Reorder mode (RAW12), to ensure that AES-CMAC calculation for the preceding selected row is completed before the next selected row is input for AES-CMAC calculation. Note: Row information format is defined by Samsung, which is described in ‘5 Key sharing’ chapter in S5K3B6SA - Cybersecurity Application note documnet. | E9: CAL 2 | F9: Test | G9: 1. Verify that, for Merge Compressed or Merged output modes using RAW12, RAW14, RAW16, RAW20, or RAW24, the configured row interval is at least 10. 2. Verify that, for Line Reorder mode using RAW12, the configured row interval is at least 30. 3. Measure or inspect the timing of AES-CMAC processing for each selected row and verify that processing of the preceding selected row is completed before the next selected row is input. 4. Verify that unsupported mode/format combinations are not assigned an interval based on an unrelated mode's minimum. | I9: MVC-103055 | J9: CS-SOW1-008 | K9: System | L9: Not started
A10: MVC-106574 | B10: 2.2.3.3-3 | C10: Secure Communication (SOW2 - SOW1) > Row information requirements | D10: The system shall ensure that the selected row range does not exceed the total vertical data size, including the image data and embedded header and statistics data, according to the following constraint: start + 1 + (interval + 1) × (total − 1) ≤ ysize_image + ysize_embedded_data where start is the starting row, interval is the row interval, total is the number of selected rows, and ysize_image and ysize_embedded_data are the vertical sizes of the image and embedded data. | E10: CAL 2 | F10: Test | G10: 1. Verify that the row-selection configuration uses the constraint start + 1 + (interval + 1) × (total − 1) ≤ ysize_image + ysize_embedded_data. 2. Configure valid values for which the expression is exactly equal to the total vertical data size and verify that the configuration is accepted. 3. Configure values for which the expression exceeds the total vertical data size by one row and verify that the configuration is rejected or corrected before use. 4. Test the minimum supported start, interval, and total values. 5. Verify that the calculation uses the actual configured image and embedded-data vertical sizes and avoids integer overflow or truncation | I10: MVC-103055 | J10: CS-SOW1-009 | K10: System | L10: Not started
A11: MVC-106568 | B11: 2.2.3.4-1 | C11: Secure Communication (SOW2 - SOW1) > Key Sharing Requirements | D11: The system shall generate a 256-bit cryptographically random session key (SSK) following successful authentication. | E11: CAL 2 | F11: Test | G11: 1. Complete SOW1 authentication successfully and trigger session-key generation. 2. Verify that the generated SSK has a length of exactly 256 bits. 3. Verify that session-key generation does not occur as a result of failed authentication. 4. Establish multiple independent sessions and verify that a new SSK is generated for each session. 5. Verify that the key is passed to the intended cryptographic operations without unintended truncation or alteration. | I11: MVC-103057 | J11: CS-SOW1-010 | K11: System | L11: Not started
A12: MVC-106560 | B12: 2.2.3.4-2 | C12: Secure Communication (SOW2 - SOW1) > Key Sharing Requirements | D12: The system shall use a CSPRNG compliant with NIST SP 800-90A and seeded by a hardware TRNG to generate the 256-bit session key. | E12: CAL 2 | F12: Test | G12: 1. Verify that the configured CSPRNG follows the applicable NIST SP 800-90A requirements. 2. Verify that its entropy source is the hardware TRNG and that the TRNG output is supplied through the approved seeding mechanism. 3. Verify that the random-generation implementation reports errors if required initialization, entropy acquisition, or random generation fails. 4. Simulate or inject a controlled RNG/TRNG failure and verify that a new SSK is not generated using an insecure fallback. 5. Verify that session establishment does not continue using an invalid or unavailable session key. | I12: MVC-103042 | J12: CS-SOW1-011 | K12: System | L12: Not started
A13: MVC-106577 | B13: 2.2.3.4-3 | C13: Secure Communication (SOW2 - SOW1) > Key Sharing Requirements | D13: Following successful authentication, The system shall extract 2048-bit device public key from the Imager's authentication data. | E13: CAL 2 | F13: Test | G13: 1. Provide valid authentication data containing the Imager's 2048-bit device public key. 2. Complete SOW1 authentication successfully. 3. Verify that the system extracts the device public key from the correct field and that the extracted key matches the reference key. 4. Verify that the extracted key is passed to the session-key encryption operation without truncation or unintended modification. 5. Provide missing, malformed, or invalid public-key data and verify that it is not used for session-key encryption. | I13: MVC-103040 | J13: CS-SOW1-012 | K13: System | L13: Not started
... A31: MVC-109121 | B31: 2.2.3.6-4 | C31: Secure Communication (SOW2 - SOW1) > SOW1 Commands Requirements (SOW2 -> SOW1) | D31: The system shall include a monotonically increasing Counter in each protected SOW1 control command. | E31: CAL 2 | F31: Test | G31: 1. Generate and transmit successive protected SOW1 control commands and inspect the counter field of each message. 2. Verify that the counter increases monotonically for successive commands within a session. 3. Verify that the counter is included in every protected command using the specified encoding and field position. 4. Verify that the counter does not repeat or decrease during normal operation. 5. Test the defined counter-maximum condition and verify that the system follows the approved exhaustion/rollover policy without silently violating monotonicity. 6. Verify the counter behavior after session termination and establishment of a new session according to the specified initialization policy. | I31: MVC-113702 | J31: CS-SOW1-030 | K31: System | L31: Not started

Sheet Template
A1: Feature | B1: Req ID | C1: Requirement text | D1: Source document and version | E1: Priority | F1: Security domain | G1: CS test case ID(s) | H1: Test level | I1: Test status | J1: Open question / notes
